<!-- NOTE: the joint limits and references have not been set. If using -->
<!-- this to control a real ur5, make sure they align with the values -->
<!-- used in the real arm firmware -->
<!-- Masses and center-of-masses taken from: www.universal-robots.com/
        how-tos-and-faqs/faq/ur-faq/
        parameters-for-calculations-of-kinematics-and-dynamics-45257/ -->
<!-- Principle moments of inertia not provided, set all to 0.1. -->
<!-- Inertia parameters provided at link below, not sure of accuracy so not used:
        http://hades.mech.northwestern.edu/images/4/49/UR5-URDF.pdf -->
<mujoco model="ur5">
    <compiler angle="radian" meshdir="meshes" balanceinertia="true"/>

    <default>
        <light castshadow="false" diffuse="1 1 1" />
        <!-- <camera fovy="20" pos="0 0 0" mode="fixed"/> -->
        <!-- <camera mode="fixed" fovy="45" pos="-2 0 0.3" xyaxes="0 -1 0 0 0 1"/> -->
    </default>

    <custom>
        <!-- <numeric name="START_ANGLES" data="0 0.60688276 -2.29695964 0 1.57 3.99226281 0.1"/> -->
        <numeric name="START_ANGLES" data="0 0.4 -2.3 0.41 1.57 0 0"/>
        <numeric name="N_GRIPPER_JOINTS" data="1" />
        <text name="google_id" data="1SjWRUl-D1FZ5fB2cy4jF4X9wTsQ5LWzo"/>
    </custom>

    <asset>
        <!-- arm models -->
        <mesh file="ur5/link0.stl"/>
        <mesh file="ur5/link1.stl"/>
        <mesh file="ur5/link1_cap.stl" />
        <mesh file="ur5/link1_connector.stl" />
        <mesh file="ur5/link2.stl" />
        <mesh file="ur5/link2_tube.stl" />
        <mesh file="ur5/link2_cap.stl" />
        <mesh file="ur5/link2_connector.stl" />
        <mesh file="ur5/link3a.stl" />
        <mesh file="ur5/link3a_connector.stl" />
        <mesh file="ur5/link3_tube.stl" />
        <mesh file="ur5/link3_cap.stl" />
        <mesh file="ur5/link3b.stl" />
        <mesh file="ur5/link3b_connector.stl" />
        <mesh file="ur5/link3b_connector2.stl"/>
        <mesh file="ur5/link4.stl" />
        <mesh file="ur5/link4_cap.stl" />
        <mesh file="ur5/link4_connector.stl" />
        <mesh file="ur5/link5.stl" />
        <mesh file="ur5/link5_cap.stl" />
        <mesh file="ur5/link5_connector.stl" />
        <mesh file="ur5/link6.stl" />
        <mesh file="ur5/link6_connector.stl" />
        <mesh name="robotiq_arg2f_base_link" file="robotiq_85_gripper/robotiq_arg2f_base_link.stl" />
        <mesh name="robotiq_arg2f_85_outer_knuckle" file="robotiq_85_gripper/robotiq_arg2f_85_outer_knuckle.stl" scale="0.001 0.001 0.001" />
        <mesh name="robotiq_arg2f_85_outer_finger" file="robotiq_85_gripper/robotiq_arg2f_85_outer_finger.stl" scale="0.001 0.001 0.001" />
        <mesh name="robotiq_arg2f_85_inner_finger" file="robotiq_85_gripper/robotiq_arg2f_85_inner_finger.stl" scale="0.001 0.001 0.001" />
        <mesh name="robotiq_arg2f_85_inner_knuckle" file="robotiq_85_gripper/robotiq_arg2f_85_inner_knuckle.stl" scale="0.001 0.001 0.001" />
        <mesh name="robotiq_arg2f_85_outer_knuckle_vis" file="robotiq_85_gripper/robotiq_arg2f_85_outer_knuckle_vis.stl" scale="0.001 0.001 0.001" />
        <mesh name="robotiq_arg2f_85_outer_finger_vis" file="robotiq_85_gripper/robotiq_arg2f_85_outer_finger_vis.stl" scale="0.001 0.001 0.001" />
        <mesh name="robotiq_arg2f_85_inner_finger_vis" file="robotiq_85_gripper/robotiq_arg2f_85_inner_finger_vis.stl" scale="0.001 0.001 0.001" />
        <mesh name="robotiq_arg2f_85_inner_knuckle_vis" file="robotiq_85_gripper/robotiq_arg2f_85_inner_knuckle_vis.stl" scale="0.001 0.001 0.001" />
        <texture name="floor_tile" file="meshes/ur5/floor_tile.png" width="3000" height="3000" type="2d"/>
        <material name="tile" texture="floor_tile" specular="0" shininess="0" reflectance="0" emission="1" />
        <material name="silver" specular="1" shininess="0.5" reflectance="1" emission="0.25" rgba="0.82 0.82 0.82 1"/>
        <material name="grey" specular="1" shininess="0.5" reflectance="1" emission="0.1" rgba="0.5 0.5 0.5 1"/>
        <material name="blue" specular="1" shininess="0.5" reflectance="1" emission="0" rgba="0.678 0.847 0.902 1"/>
        <material name="black" specular="1" shininess="0.5" reflectance="1" emission="0" rgba="0.2 0.2 0.2 1"/>
    </asset>



    <worldbody>
        <geom name="floor_grey_tile" pos="0 0 -0.001" size="0.75 0.75 0.05" type="plane" material="tile"/>
        <camera name='111' fovy="60" pos="0 1.5 1" euler="-1 0 3.14" mode="fixed"/>

        <light directional="true" pos="-0.5 0.5 3" dir="0 0 -1" />

        <body name="base_link" pos="0 -0.3 0">
            <geom name="link0" type="mesh" mesh="link0" pos="0 0 0"/>

            <body name="link1" pos="0 0 0.0213">
                <joint name="joint0" axis="0 0 1" pos="0 0 0"/>
                <inertial pos="0 -0.02561 0.00193" mass="3.761" diaginertia="0.1 0.1 0.1"/>
                <geom name="link1_connector" type="mesh" mesh="link1_connector" pos="0 0 0" material="black"
                    conaffinity="32" contype="32"/>
                <geom name="link1" type="mesh" mesh="link1" pos="0 0 0.008" material="grey"/>
                <geom name="link1_cap" type="mesh" mesh="link1_cap" pos="0 0 .1025" material="blue"/>

                <body name="link2" pos="-0.0663 0 0.0679">
                    <joint name="joint1" axis="-1 0 0" pos="0 0 0"/>
                    <inertial pos="-0.04706 0 0.2125" mass="8.058" diaginertia="0.1 0.1 0.1"/>
                    <geom name="link2_connector" type="mesh" mesh="link2_connector" pos="0 0 0" material="black"
                        conaffinity="32" contype="32"/>
                    <geom name="link2" type="mesh" mesh="link2" pos="-0.008 0 0" material="grey"/>
                    <geom name="link2_cap" type="mesh" mesh="link2_cap" pos="-0.1015 0 -0.0025" material="blue"/>
                    <geom name="link2_tube" type="mesh" mesh="link2_tube" pos="-0.0679 0 0.066" material="silver"/>

                    <body name="link3" pos="-0.008 0 0.425">
                        <joint name="joint2" axis="1 0 0" pos="0 0 0"/>
                        <inertial pos="0.0478 0 0.15" mass="2.846" diaginertia="0.1 0.1 0.1"/>
                        <geom name="link3a_connector" type="mesh" mesh="link3a_connector" pos="0 0 0" material="black"
                            conaffinity="32" contype="32"/>
                        <geom name="link3a" type="mesh" mesh="link3a" pos="0.008 0 0" material="grey"/>
                        <geom name="link3_tube" type="mesh" mesh="link3_tube" pos="0.059 0 0.066" material="silver"/>
                        <geom name="link3b_connector" type="mesh" mesh="link3b_connector" pos="0.059 0 0.3418" material="black" />
                        <geom name="link3b_connector2" type="mesh" mesh="link3b_connector2" pos="0.059 0 0.34" material="grey"
                            conaffinity="32" contype="32"/>
                        <geom name="link3b" type="mesh" mesh="link3b" pos="0.059 0 0.347" material="grey"/>
                        <geom name="link3_cap" type="mesh" mesh="link3_cap" pos="0.0837 0 0.392" material="blue"/>

                        <body name="link4" pos="0.0173 0 0.3922">
                            <joint name="joint3" axis="-1 0 0" pos="0 0 0"/>
                            <inertial pos="-0.05796 -0.0018 0" mass="1.37" diaginertia="0.1 0.1 0.1"/>
                            <geom name="link4_connector" type="mesh" mesh="link4_connector" pos="0 0 0" material="black"
                                conaffinity="32" contype="32"/>
                            <geom name="link4" type="mesh" mesh="link4" pos="-0.008 0 0" material="grey"/>
                            <geom name="link4_cap" type="mesh" mesh="link4_cap" pos="-0.05325 0 -0.0247" material="blue"/>

                            <body name="link5" pos="-0.05325 0 0.04165">
                                <joint name="joint4" axis="0 0 1" pos="0 0 0"/>
                                <inertial pos="0.0018 0 0.01634" mass="1.3" diaginertia="0.1 0.1 0.1"/>
                                <geom name="link5_connector" type="mesh" mesh="link5_connector" pos="0 0 0" material="black"
                                    conaffinity="32" contype="32"/>
                                <geom name="link5" type="mesh" mesh="link5" pos="0 0 0.0079" material="grey"/>
                                <geom name="link5_cap" type="mesh" mesh="link5_cap" pos="0.025 0 0.053" material="blue"/>

                                <body name="link6" pos="-0.04165 0 0.05305">
                                    <joint name="joint5" axis="-1 0 0" pos="0 0 0"/>
                                    <inertial pos="-0.038841 0 0" mass="0.365" diaginertia="0.1 0.1 0.1"/>
                                    <geom name="link6_connector" type="mesh" mesh="link6_connector" pos="0 0 0" material="black"
                                        conaffinity="32" contype="32"/>
                                    <geom name="link6" type="mesh" mesh="link6" pos="-0.008 0 0" material="silver"/>

                                    <body name="EE" pos="-0.177 0 0" euler="0 0 0"/>

                                    <body name="robotiq_85_adapter_link" pos="-0.04 0 0" euler="0 -1.57 0">
                                        <!-- <site name="ft_frame" pos="0 0 0" size="0.01 0.01 0.01" rgba="1 0 0 1" type="sphere" group="1" /> -->
                                        <body name="eef" pos="0 0 0.145" quat="0.707105 0 0 -0.707105">
                                            <!-- <site name="grip_site" pos="0 0 0" size="0.01 0.01 0.01" rgba="1 0 0 0.5" type="sphere" group="1"/> -->
                                            <site name="ee_x" pos="0.1 0 0" size="0.005 .1"  quat="0.707105  0 0.707108 0 " rgba="1 0 0 0" type="cylinder" group="1"/>
                                            <site name="ee_y" pos="0 0.1 0" size="0.005 .1" quat="0.707105 0.707108 0 0" rgba="0 1 0 0" type="cylinder" group="1"/>
                                            <site name="ee_z" pos="0 0 0.1" size="0.005 .1" quat="1 0 0 0" rgba="0 0 1 0" type="cylinder" group="1"/>
                                            <!-- <site name="grip_site_cylinder" pos="0 0 0" size="0.005 10" rgba="0 1 0 0.3" type="cylinder" group="1"/> -->
                                        </body>
                                        <inertial pos="0 0 0" mass="0.01" diaginertia="0.001 0.001 0.001" />
                                        <geom type="mesh" contype="0" conaffinity="0" group="1" rgba="0.1 0.1 0.1 1" name="hand_visual" mesh="robotiq_arg2f_base_link" />
                                        <geom type="mesh" group="0" rgba="0.1 0.1 0.1 1" mesh="robotiq_arg2f_base_link" name="hand_collision" />
                                        <body name="left_outer_knuckle" pos="0 -0.0306011 0.054904" quat="0 0 0 1">
                                            <inertial pos="0.000163875 0.0554825 -0.0100755" quat="0.920541 0.390623 -0.00362953 0.00231744" mass="0.0311462" diaginertia="5.11372e-05 4.89464e-05 4.95906e-06" />
                                            <joint name="finger_joint" pos="0 0 0" axis="1 0 0" limited="true" range="0 0.8" />
                                            <geom type="mesh" contype="0" conaffinity="0" group="1" rgba="0.792157 0.819608 0.933333 1" name="left_outer_knuckle_visual" mesh="robotiq_arg2f_85_outer_knuckle_vis" />
                                            <!-- <geom type="mesh" group="0" rgba="0.792157 0.819608 0.933333 1" mesh="robotiq_arg2f_85_outer_knuckle" name="left_outer_knuckle_collision" solref="0.01 0.25" /> -->
                                            <geom pos="0 0.0315 -0.0041" type="mesh" contype="0" conaffinity="0" group="1" rgba="0.1 0.1 0.1 1" name="left_outer_finger_visual" mesh="robotiq_arg2f_85_outer_finger_vis" />
                                            <!-- <geom pos="0 0.0315 -0.0041" type="mesh" group="0" rgba="0.1 0.1 0.1 1" mesh="robotiq_arg2f_85_outer_finger" name="left_outer_finger_collision" solref="0.01 0.25" /> -->
                                            <body name="left_inner_finger" pos="0 0.0376 0.043">
                                                <inertial pos="0.000199506 0.0032692 0.00175282" quat="0.933621 0.35825 -0.00273441 0.00104851" mass="0.0156391" diaginertia="1.57977e-05 1.51089e-05 1.4647e-06" />
                                                <!-- <joint name="left_inner_finger_joint" pos="0 0 0" axis="1 0 0" limited="true" range="-0.8757 0.8757" /> -->
                                                <joint name="left_inner_finger_joint" pos="0 0 0" axis="1 0 0" limited="true" range="-0.8757 0.8757" />
                                                <geom type="mesh" contype="0" conaffinity="0" group="1" rgba="0.1 0.1 0.1 1" name="left_inner_finger_visual" mesh="robotiq_arg2f_85_inner_finger_vis" />
                                                <!-- <geom type="mesh" group="0" rgba="0.1 0.1 0.1 1" mesh="robotiq_arg2f_85_inner_finger" name="left_inner_finger_collision" solref="0.01 0.25" /> -->
                                                <geom size="0.011 0.003175 0.01875" pos="0 -0.0220203 0.03242" type="box" contype="1" conaffinity="1" group="1" rgba="0.9 0.9 0.9 1" name="left_fingertip_visual" solimp="0.99 0.99 0.01" solref="0.01 1"  condim="4" friction="0.8 0.8 10"/>
                                                <!-- <geom size="0.011 0.003175 0.01875" pos="0 -0.0220203 0.03242" type="box" group="0" rgba="0.9 0.9 0.9 1" name="left_fingertip_collision" solref="0.01 0.25" /> -->
                                                <!-- <geom size="0.010 0.001 0.01675" pos="0 -0.0245203 0.03242" type="box" group="0" name="left_fingerpad_collision" /> -->
                                            </body>
                                        </body>
                                        <body name="left_inner_knuckle" pos="0 -0.0127 0.06142" quat="0 0 0 1">
                                            <inertial pos="0.000123012 0.0507851 0.00103969" quat="0.497203 0.502496 -0.507943 0.492221" mass="0.0271177" diaginertia="2.83809e-05 2.61936e-05 2.81319e-06" />
                                            <joint name="left_inner_knuckle_joint" pos="0 0 0" axis="1 0 0" limited="true" range="0 0.8757" />
                                            <geom type="mesh" contype="0" conaffinity="0" group="1" rgba="0.1 0.1 0.1 1" name="left_inner_knuckle_visual" mesh="robotiq_arg2f_85_inner_knuckle_vis" />
                                            <!-- <geom type="mesh" group="0" rgba="0.1 0.1 0.1 1" mesh="robotiq_arg2f_85_inner_knuckle" name="left_inner_knuckle_collision" /> -->
                                        </body>
                                        <body name="right_outer_knuckle" pos="0 0.0306011 0.054904">
                                            <inertial pos="0.000163875 0.0554825 -0.0100755" quat="0.920541 0.390623 -0.00362953 0.00231744" mass="0.0311462" diaginertia="5.11372e-05 4.89464e-05 4.95906e-06" />
                                            <joint name="right_outer_knuckle_joint" pos="0 0 0" axis="1 0 0" limited="true" range="0 0.8" />
                                            <geom type="mesh" contype="0" conaffinity="0" group="1" rgba="0.792157 0.819608 0.933333 1" name="right_outer_knuckle_visual" mesh="robotiq_arg2f_85_outer_knuckle_vis" />
                                            <!-- <geom type="mesh" group="0" rgba="0.792157 0.819608 0.933333 1" mesh="robotiq_arg2f_85_outer_knuckle" name="right_outer_knuckle_collision" solref="0.01 0.25" /> -->
                                            <geom pos="0 0.0315 -0.0041" type="mesh" contype="0" conaffinity="0" group="1" rgba="0.1 0.1 0.1 1" name="right_outer_finger_visual" mesh="robotiq_arg2f_85_outer_finger_vis" />
                                            <!-- <geom pos="0 0.0315 -0.0041" type="mesh" group="0" rgba="0.1 0.1 0.1 1" mesh="robotiq_arg2f_85_outer_finger" name="right_outer_finger_collision" solref="0.01 0.25" /> -->
                                            <body name="right_inner_finger" pos="0 0.0376 0.043">
                                                <inertial pos="0.000199506 0.0032692 0.00175282" quat="0.933621 0.35825 -0.00273441 0.00104851" mass="0.0156391" diaginertia="1.57977e-05 1.51089e-05 1.4647e-06" />
                                                <joint name="right_inner_finger_joint" pos="0 0 0" axis="1 0 0" limited="true" range="-0.8757 0.8757" />
                                                <geom type="mesh" contype="0" conaffinity="0" group="1" rgba="0.1 0.1 0.1 1" name="right_inner_finger_visual" mesh="robotiq_arg2f_85_inner_finger_vis" />
                                                <!-- <geom type="mesh" group="0" rgba="0.1 0.1 0.1 1" mesh="robotiq_arg2f_85_inner_finger" name="right_inner_finger_collision" solref="0.01 0.25" /> -->
                                                <geom size="0.011 0.003175 0.01875" pos="0 -0.0220203 0.03242" type="box" contype="1" conaffinity="1" group="1" rgba="0.9 0.9 0.9 1" name="right_fingertip_visual" solimp="0.99 0.99 0.01" solref="0.01 1"  condim="4" friction="0.8 0.8 10"/>
                                                <!-- <geom size="0.011 0.003175 0.01875" pos="0 -0.0220203 0.03242" type="box" group="0" rgba="0.9 0.9 0.9 1" name="right_fingertip_collision" solref="0.01 0.25" /> -->
                                                <!-- <geom size="0.010 0.001 0.01675" pos="0 -0.0245203 0.03242" type="box" group="0" name="right_fingerpad_collision" /> -->
                                            </body>
                                        </body>
                                        <body name="right_inner_knuckle" pos="0 0.0127 0.06142">
                                            <inertial pos="0.000123012 0.0507851 0.00103969" quat="0.497203 0.502496 -0.507943 0.492221" mass="0.0271177" diaginertia="2.83809e-05 2.61936e-05 2.81319e-06" />
                                            <joint name="right_inner_knuckle_joint" pos="0 0 0" axis="1 0 0" limited="true" range="0 0.8757" />
                                            <geom type="mesh" contype="0" conaffinity="0" group="1" rgba="0.1 0.1 0.1 1" name="right_inner_knuckle_visual" mesh="robotiq_arg2f_85_inner_knuckle_vis" />
                                            <!-- <geom type="mesh" group="0" rgba="0.1 0.1 0.1 1" mesh="robotiq_arg2f_85_inner_knuckle" name="right_inner_knuckle_collision" /> -->
                                        </body>
                                    </body>



                                </body>
                            </body>
                        </body>
                    </body>
                </body>
            </body>
        </body>

        <body name="target2" pos="0.5 0.5 0.05">
            <joint type="free" name="target2"/>
            <geom name="target2" type="box" size="0.02 0.02 0.05" rgba=".9 0 0 1" contype="1" conaffinity="1" solimp="0.99 0.99 0.01" solref="0.01 1" condim="4" friction="0.8 0.8 10"/>
            <inertial pos="0 0 0" mass="0.1" diaginertia="0.1 0.1 0.1"/>
        </body>

    </worldbody>

    <actuator>
        <motor name="joint0_motor" joint="joint0"/>
        <motor name="joint1_motor" joint="joint1"/>
        <motor name="joint2_motor" joint="joint2"/>
        <motor name="joint3_motor" joint="joint3"/>
        <motor name="joint4_motor" joint="joint4"/>
        <motor name="joint5_motor" joint="joint5"/>
        <motor name="finger_joint_motor" joint="finger_joint"/>
    </actuator>

    <equality>
        <joint joint1="finger_joint" joint2="right_outer_knuckle_joint" polycoef="0 1 0 0 0"/>
        <joint joint1="finger_joint" joint2="left_inner_knuckle_joint" polycoef="0 1 0 0 0"/>
        <joint joint1="finger_joint" joint2="right_inner_knuckle_joint" polycoef="0 1 0 0 0"/>
        <joint joint1="finger_joint" joint2="left_inner_finger_joint" polycoef="0 -1 0 0 0"/>
        <joint joint1="finger_joint" joint2="right_inner_finger_joint" polycoef="0 -1 0 0 0"/>
    </equality>

</mujoco>

