<!-- NOTE: the joint limits and references have not been set. If using -->
<!-- this to control a real ur5, make sure they align with the values -->
<!-- used in the real arm firmware -->
<!-- Masses and center-of-masses taken from: www.universal-robots.com/
        how-tos-and-faqs/faq/ur-faq/
        parameters-for-calculations-of-kinematics-and-dynamics-45257/ -->
<!-- Principle moments of inertia not provided, set all to 0.1. -->
<!-- Inertia parameters provided at link below, not sure of accuracy so not used:
        http://hades.mech.northwestern.edu/images/4/49/UR5-URDF.pdf -->
<mujoco model="ur5">
    <compiler angle="radian" meshdir="meshes" balanceinertia="true"/>

    <size njmax="8000" nconmax="4000"/>

    <default>
        <light castshadow="false" diffuse="1 1 1" />
        <!-- <camera fovy="20" pos="0 0 0" mode="fixed"/> -->
        <!-- <camera mode="fixed" fovy="45" pos="-2 0 0.3" xyaxes="0 -1 0 0 0 1"/> -->
    </default>

    <custom>
        <!-- <numeric name="START_ANGLES" data="0 0.60688276 -2.29695964 0 1.57 3.99226281 0.1"/> -->
        <numeric name="START_ANGLES" data="1.63603335 4.12186299 0.442252554 1.65288766 3.13380172 1.61742328 0"/>
        <numeric name="N_GRIPPER_JOINTS" data="1" />
        <text name="google_id" data="1SjWRUl-D1FZ5fB2cy4jF4X9wTsQ5LWzo"/>
    </custom>

    <asset>
        <!-- arm models -->
        <mesh file="link0.STL" />
        <mesh file="link1.STL"/>
        <mesh file="link2.STL"/>
        <mesh file="link3.STL"/>
        <mesh file="link4_5.STL"/>
        <mesh file="hand_3finger.STL"/>
        <mesh file="finger_distal.STL"/>
        <mesh file="finger_proximal.STL"/>
        <mesh file="ring_big.STL"/>
        <mesh file="ring_small.STL"/>

        <texture name="floor_tile" file="meshes/floor_tile.png" width="3000" height="3000" type="2d"/>
        <material name="tile" texture="floor_tile" specular="0" shininess="0" reflectance="0" emission="1" />

        <material name="carbon" specular="1" shininess="1" reflectance="1" rgba="0.05 0.05 0.05 1" emission="1" />
        <material name="grey_plastic" specular="0.5" shininess="0" reflectance="0" rgba="0.12 0.14 0.14 1" emission="1" />

        <texture name="abr_logo" file="meshes/abr_logo.png" width="193" height="193" type="2d"/>
        <material name="logo" texture="abr_logo"/>

        <texture name="abr_logo_flip" file="meshes/abr_logo.png" width="193" height="193" type="2d" hflip="true"/>
        <material name="logo_flip" texture="abr_logo_flip"/>

        <texture name="foam_blocks" file="meshes/foam_blocks.png" width="2744" height="2744" type="2d"/>
        <material name="foam" texture="foam_blocks" specular="0" shininess="0" reflectance="0" emission="1" />


        <mesh file="objects/bread.stl" name="bread_mesh" scale="1 1 1.25"/>
        <texture file="meshes/objects/textures/bread.png" type="2d" name="tex-bread" />
        <material name="bread" reflectance="0.7" texrepeat="15 15" texture="tex-bread" texuniform="true"/>

        <mesh file="objects/bottle.stl" name="bottle_mesh"/>
        <!-- <texture type="skybox" file="meshes/objects/textures/glass.png" name="tex-glass"/> -->
        <texture type="2d" file="meshes/objects/textures/glass.png" name="tex-glass"/>
        <material name="glass" reflectance="0.5" texrepeat="5 5" texture="tex-glass" texuniform="true"/>

        <mesh file="objects/can.msh" name="can_mesh"/>
        <texture file="meshes/objects/textures/coke_can.png" name="tex-can" type="2d"/>
        <material name="coke" reflectance="0.7" texrepeat="5 5" texture="tex-can" texuniform="true"/>

        <texture file="meshes/objects/textures/pepsi_can.png" name="tex-pepsi" type="2d"/>
        <material name="pepsi" reflectance="0.7" texrepeat="5 5" texture="tex-pepsi" texuniform="true"/>

        <mesh file="objects/cereal.msh" name="cereal_mesh"/>
        <texture type="2d" file="meshes/objects/textures/cereal.png" rgb1="1 1 1" name="tex-cereal"/>
        <material name="cereal" reflectance="0.5" texrepeat="1 1" texture="tex-cereal" texuniform="false"/>

        <mesh file="objects/lemon.msh" name="lemon_mesh" scale="1.5 1 1"/>
        <texture file="meshes/objects/textures/lemon.png" type="2d" name="tex-lemon"/>
        <material name="lemon" reflectance="0.7" texrepeat="60 50" texture="tex-lemon" texuniform="true"/>

        <mesh file="objects/milk.msh" name="milk_mesh" scale="0.9 0.9 0.9"/>
        <texture file="meshes/objects/textures/ceramic.png" name="tex-ceramic" type="2d"/>
        <material name="ceramic" reflectance="0.5" texrepeat="1 1" texture="tex-ceramic" texuniform="true"/>

        <texture file="meshes/objects/textures/red-wood.png" type="cube" name="red-wood" />
        <material name="plate_mat" texture="red-wood" texrepeat="3 3" specular="0.4" shininess="0.1" />

        <texture file="meshes/objects/textures/steel-scratched.png" type="cube" name="steel-metal"/>
        <material name="smetal" reflectance="1.0" shininess="1.0" specular="1.0" texrepeat="1 1" texture="steel-metal" texuniform="true"/>

        <texture file="meshes/objects/textures/brass-ambra.png" type="cube" name="brass-metal"/>
        <material name="bmetal"  reflectance="1.0" shininess="1.0" specular="1.0" texrepeat="1 1" texture="brass-metal" texuniform="true"/>

        <mesh name="004_sugar_box" file="objects/004_sugar_box.msh" scale="1 1 1"/>
        <texture name="004_sugar_box" type="2d" file="meshes/objects/textures/004_sugar_box.png"/>
        <material name="004_sugar_box" texture="004_sugar_box"/>

        <mesh name="002_master_chef_can" file="objects/002_master_chef_can.msh" scale="1 1 1"/>
        <texture name="002_master_chef_can" type="2d" file="meshes/objects/textures/002_master_chef_can.png"/>
        <material name="002_master_chef_can" texture="002_master_chef_can"/>

        <mesh name="003_cracker_box" file="objects/003_cracker_box.msh" scale="1 1 1"/>
        <texture name="003_cracker_box" type="2d" file="meshes/objects/textures/003_cracker_box.png"/>
        <material name="003_cracker_box" texture="003_cracker_box"/>

        <mesh name="005_tomato_soup_can" file="objects/005_tomato_soup_can.msh" scale="1 1 1"/>
        <texture name="005_tomato_soup_can" type="2d" file="meshes/objects/textures/005_tomato_soup_can.png"/>
        <material name="005_tomato_soup_can" texture="005_tomato_soup_can"/>

        <mesh name="006_mustard_bottle" file="objects/006_mustard_bottle.msh" scale="1 1 1"/>
        <texture name="006_mustard_bottle" type="2d" file="meshes/objects/textures/006_mustard_bottle.png"/>
        <material name="006_mustard_bottle" texture="006_mustard_bottle"/>

        <mesh name="007_tuna_fish_can" file="objects/007_tuna_fish_can.msh" scale="1 1 1"/>
        <texture name="007_tuna_fish_can" type="2d" file="meshes/objects/textures/007_tuna_fish_can.png"/>
        <material name="007_tuna_fish_can" texture="007_tuna_fish_can"/>

        <mesh name="008_pudding_box" file="objects/008_pudding_box.msh" scale="1 1 1"/>
        <texture name="008_pudding_box" type="2d" file="meshes/objects/textures/008_pudding_box.png"/>
        <material name="008_pudding_box" texture="008_pudding_box"/>

        <mesh name="009_gelatin_box" file="objects/009_gelatin_box.msh" scale="1 1 1"/>
        <texture name="009_gelatin_box" type="2d" file="meshes/objects/textures/009_gelatin_box.png"/>
        <material name="009_gelatin_box" texture="009_gelatin_box"/>

        <mesh name="010_potted_meat_can" file="objects/010_potted_meat_can.msh" scale="1 1 1"/>
        <texture name="010_potted_meat_can" type="2d" file="meshes/objects/textures/010_potted_meat_can.png"/>
        <material name="010_potted_meat_can" texture="010_potted_meat_can"/>

        <mesh name="035_power_drill" file="objects/035_power_drill.msh" scale="1 1 1"/>
        <texture name="035_power_drill" type="2d" file="meshes/objects/textures/035_power_drill.png"/>
        <material name="035_power_drill" texture="035_power_drill"/>
    </asset>



    <worldbody>
<!--         <geom name="floor_foam_block" pos="0 0 0" size="0.5 0.5 0.05" type="plane" rgba="1 0.83 0.61 1" material="foam"/> -->
        <geom name="floor_grey_tile" pos="0 0 -0.001" size="0.75 0.75 0.05" type="plane" material="tile"/>
        <camera name='111' fovy="60" pos="0 1.5 1" euler="-1 0 3.14" mode="fixed"/>

        <!-- control visualizations -->
        <body name="hand" pos="0 0 -0.15" mocap="true">
            <geom type="box" size=".002 .004 .006" rgba="0 .9 0 .5" contype="2" conaffinity="2"/>
        </body>

        <body name="target" pos="0 0 -0.15" mocap="true">
            <geom name="target" type="sphere" size="0.05" rgba=".9 0 0 .5" contype="4" conaffinity="4"/>
        </body>

        <body name="target_orientation" pos="0 0 -0.15" mocap="true">
            <geom type="box" size=".02 .04 .06" rgba=".9 0 0 .5" contype="8" conaffinity="8"/>
        </body>

        <body name="path_planner" pos="0 0 -0.15" mocap="true">
            <geom type="sphere" size="0.05" rgba="0 1 1 0.5" contype="16" conaffinity="16"/>
        </body>

        <body name="path_planner_orientation" pos="0 0 -0.15" mocap="true">
            <geom type="box" size=".02 .04 .06" rgba="0 1 1 .5" contype="32" conaffinity="32"/>
        </body>

        <body name="obstacle" pos="0 0 -0.15" mocap="true">
            <geom type="sphere" size="0.05" rgba="0 0 1 1"/>
        </body>

        <light directional="true" pos="-0.5 0.5 3" dir="0 0 -1" />

        <body name="base_link" pos="0 -0.3 0">
            <geom name="link0" type="mesh" mesh="link0" pos="0 0 0" material="carbon"/>
            <inertial pos="0.000000 0.000000 0.125500" mass="1.226" diaginertia="0.25 0.25 0.25"/>
            <geom type="sphere" size="0.025" pos="0.000000 0.000000 0.125500" rgba="1 0.5 0 1"/>

            <body name="link1" pos="0 0 0.157">
                <inertial pos="-0.000042 -0.001285 0.112784" mass="0.754000" diaginertia="0.3 0.3 0.3"/>
                <geom name="link1" type="mesh" mesh="link1" pos="0 0 0" euler="0 3.14 0" material="carbon"/>
                <!-- <geom name="ring0" type="mesh" mesh="ring_big" material="grey_plastic"/> -->
                <geom name="joint_logo0" type="cylinder" size="0.032 0.005" material="logo" pos="0 -0.0364 0.1186" euler="1.6 0 0"/>
                <joint name="joint0" axis="0 0 -1" pos="0 0 0"/>


                <body name="link2" pos="0 0.0016 0.1186">
                    <inertial pos="0.000014 0.009353 0.329006" mass="1.010000" diaginertia="0.3 0.3 0.3"/>
                    <geom name="link2" type="mesh" mesh="link2" pos="0 0 0" euler="1.57 0 3.14" material="carbon"/>
                    <geom name="ring1" type="mesh" mesh="ring_big" material="grey_plastic" euler="1.57 0 0"/>
                    <geom name="joint_logo1" type="cylinder" size="0.032 0.005" material="logo_flip" pos="0 0.038 0" euler="1.52 0 0"/>
                    <geom name="joint_logo2" type="cylinder" size="0.032 0.005" material="logo_flip" pos="0 0.0385 0.410" euler="1.62 0 0"/>
                    <joint name="joint1" pos="0 0 0" axis="0 -1 0"  ref="3.14" limited="true" range="0.872665 5.41052"/>

                    <body name="link3" pos="0 0 0.410">
                        <inertial pos="-0.000039 -0.018069 0.153270" mass="0.559000" diaginertia="0.275 0.275 0.275"/>
                        <geom name="link3" type="mesh" mesh="link3" pos="0 0 0" euler="1.57 3.14 0" material="carbon"/>
                        <geom name="ring2" type="mesh" mesh="ring_big" material="grey_plastic" euler="1.57 0 0"/>
                        <joint name="joint2" pos="0 0 0" axis="0 1 0" ref="3.14" limited="true" range="0.331613 5.95157"/>
                        <geom name="joint_logo3" type="cylinder" size="0.032 0.005" material="logo" pos="0 -0.038 0" euler="1.54 0 0"/>

                        <body name="link4" pos="0 -0.0115 0.2072">
                            <inertial pos="0.000000 0.032302 0.059705" mass="0.417000" diaginertia="0.175 0.175 0.175"/>
                            <geom name="link4" type="mesh" mesh="link4_5" euler="3.14 0 0" material="carbon"/>
                            <geom name="ring3" type="mesh" mesh="ring_small" material="grey_plastic"/>
                            <joint name="joint3" pos="0 0 0" axis="0 0 -1" ref="0"/>

                            <body name="link5" pos="0 0.037 0.0641">
                                <inertial pos="-0.000000 0.035545 0.057833" mass="0.417" diaginertia="0.175 0.175 0.175"/>
                                <geom name="link5" type="mesh" mesh="link4_5" euler="-1.0472 3.14 0" material="carbon"/>
                                <geom name="ring4" type="mesh" mesh="ring_small" material="grey_plastic" euler="-1.0471 0 0"/>
                                <joint name="joint4" pos="0 0 0" axis="0 -1.9 -1.1" ref="0"/>

                                <body name="link6" pos="0 0.037 0.0641">
                                    <inertial pos="0.000030 -0.006840 0.082220" mass="0.727000" diaginertia="0.025 0.025 0.025"/>
                                    <geom name="link6" type="mesh" mesh="hand_3finger" euler="3.14 0 0" material="carbon" solimp="0.97 0.97 0.01" solref="0.01 1" condim="6" />
                                    <geom name="ring5" type="mesh" mesh="ring_small" material="grey_plastic"/>
                                    <joint name="joint5" pos="0 0 0" axis="0 0 -1" ref="0"/>

                                    <!-- for fingertip EE -->
                                    <!-- <body name="EE" pos="0 0 0.20222" euler="0 0 0"> -->
                                    <!-- </body> -->

                                    <!-- for palm EE -->
                                    <body name="EE" pos="0 0 0.12" euler="0 0 0">
                                    </body>

                                    <body name="thumb_proximal" pos="0.002786 -0.03126 0.114668" quat="0.95922726  0.262085    0.02762996 -0.10213274">
                                        <geom name="thumb_proximal" type="mesh" mesh="finger_proximal" euler="0 -1.5707 0" friction="1 0.5 0.01" solimp="0.95 0.95 0.01 0.5 6" solref="0.01 1" condim="6" margin="0.0"/>
                                        <joint name="joint_thumb" pos="0 0 0" axis="1 0 0" ref="1.1" limited="true" range="-0.2 1.1" solimplimit="0.95 0.95 0.01" solreflimit="0.01 1" springref="0.0" damping="0.1"/>

                                        <body name="thumb_distal" pos="0 -0.003 0.044">
                                            <geom name="thumb_distal" type="mesh" mesh="finger_distal" euler="0 -1.5707 0" friction="1 0.5 0.01" solimp="0.95 0.95 0.01 0.5 6" solref="0.01 1" condim="6" margin="0.0"/>
                                            <joint name="joint_thumb_distal" pos="0 0 0" axis="-1 0 0" ref="0" limited="true" range="-0.4 0.4" stiffness="5" springref="-0.4" damping="0.5" solimplimit="0.95 0.95 0.01" solreflimit="0.01 1"/>
                                        </body>
                                    </body>

                                    <body name="index_proximal" pos="0.022256 0.027073 0.114668" quat="0.96181018 -0.25771638 0.0238668 -0.08907205">
                                        <geom name="index_proximal" type="mesh" mesh="finger_proximal" quat="5.63312174e-04  7.06824957e-01 -5.62863772e-04  7.07388045e-01" friction="1 0.5 0.01" solimp="0.95 0.95 0.01 0.5 6" solref="0.01 1" condim="6" margin="0.0"/>
                                        <joint name="joint_index" pos="0 0 0" axis="-1 0 0" ref="1.1" limited="true" range="-0.2 1.1" solimplimit="0.95 0.95 0.01" solreflimit="0.01 1" springref="0.0" damping="0.1"/>

                                        <body name="index_distal" pos="0 0.003 0.044">
                                            <geom name="index_distal" type="mesh" mesh="finger_distal" quat="5.63312174e-04  7.06824957e-01 -5.62863772e-04  7.07388045e-01" friction="1 0.5 0.01" solimp="0.95 0.95 0.01 0.5 6" solref="0.01 1" condim="6" margin="0.0"/>
                                            <joint name="joint_index_distal" pos="0 0 0" axis="1 0 0" ref="0" limited="true" range="-0.4 0.4" stiffness="5" springref="-0.4" damping="0.5" solimplimit="0.95 0.95 0.01" solreflimit="0.01 1"/>
                                        </body>
                                    </body>

                                    <body name="pinky_proximal" pos="-0.022256 0.027073 0.114816" quat="0.96181018 -0.25771638 -0.0238668 0.08907205">
                                        <geom name="pinky_proximal" type="mesh" mesh="finger_proximal" quat="5.63312174e-04  7.06824957e-01 -5.62863772e-04  7.07388045e-01" friction="1 0.5 0.01" solimp="0.95 0.95 0.01 0.5 6" solref="0.01 1" condim="6" margin="0.0"/>
                                        <joint name="joint_pinky" pos="0 0 0" axis="-1 0 0" ref="1.1" limited="true" range="-0.2 1.1" solimplimit="0.95 0.95 0.01" solreflimit="0.01 1" springref="0.0" damping="0.1"/>

                                        <body name="pinky_distal" pos="0 0.003 0.044">
                                            <geom name="pinky_distal" type="mesh" mesh="finger_distal" quat="5.63312174e-04  7.06824957e-01 -5.62863772e-04  7.07388045e-01" friction="1 0.5 0.01" solimp="0.95 0.95 0.01 0.5 6" solref="0.01 1" condim="6" margin="0.0"/>
                                            <joint name="joint_pinky_distal" pos="0 0 0" axis="1 0 0" ref="0" limited="true" range="-0.4 0.4" stiffness="5" springref="0.4" damping="0.5" solimplimit="0.95 0.95 0.01" solreflimit="0.01 1"/>
                                        </body>
                                    </body>
                                </body>
                            </body>
                        </body>
                    </body>
                </body>
            </body>
        </body>

        <body name="target2" pos="0.5 0.5 0.05">
            <joint type="free" name="target2"/>
            <geom name="target2" type="box" size="0.02 0.02 0.05" rgba=".9 0 0 1" contype="1" conaffinity="1" solimp="0.99 0.99 0.01" solref="0.01 1" condim="4" friction="0.8 0.8 10"/>
            <inertial pos="0 0 0" mass="0.1" diaginertia="0.1 0.1 0.1"/>
        </body>
<!--         <body> -->
          <body name="bread" pos="-0.1 0.5 0.03">
            <joint type="free" name="bread"/>
            <geom pos="0 0 0" mesh="bread_mesh" type="mesh" solimp="0.998 0.998 0.001" solref="0.001 1" density="50" friction="0.95 0.3 0.1"  material="bread" condim="4"/>
          </body>
<!--           <site rgba="0 0 0 0" size="0.005" pos="0 0 -0.045" name="bottom_site"/>
          <site rgba="0 0 0 0" size="0.005" pos="0 0 0.03" name="top_site"/>
          <site rgba="0 0 0 0" size="0.005" pos="0.03 0.03 0" name="horizontal_radius_site"/>
        </body> -->
        <body name="bottle" pos="0.3 0.5 0.065">
            <joint type="free" name="bottle"/>
            <geom mesh="bottle_mesh" type="mesh" solimp="0.998 0.998 0.001" solref="0.001 1" density="50" friction="0.95 0.3 0.1" material="glass" contype="1" conaffinity="1" condim="4"/>
            <!-- <geom pos="0 0 0.05" mesh="bottle_mesh" type="mesh" solimp="0.998 0.998 0.001" solref="0.001 1" density="50" friction="0.95 0.3 0.1" material="glass" group="0"/> -->
        </body>

        <body name="coke" pos="0.4 0.5 0.04">
            <joint type="free" name="can"/>
            <geom mesh="can_mesh" type="mesh" solimp="0.998 0.998 0.001" solref="0.001 1" density="50" friction="0.95 0.3 0.1" material="coke" contype="1" conaffinity="1" condim="4"/>
        </body>

        <body name="pepsi" pos="0.6 0.5 0.04">
            <joint type="free" name="pepsi"/>
            <geom mesh="can_mesh" type="mesh" solimp="0.998 0.998 0.001" solref="0.001 1" density="50" friction="0.95 0.3 0.1" material="pepsi" contype="1" conaffinity="1" condim="4"/>
        </body>

<!--         <body>
            <joint type="free" name="cereal"/>
            <geom pos="0.1 0.5 0.07" mesh="cereal_mesh" type="mesh" solimp="0.998 0.998 0.001" solref="0.001 1" density="50" friction="0.95 0.3 0.1" material="cereal" contype="1" conaffinity="1" condim="4"/>
        </body>
 -->
<!--         <body>
            <joint type="free" name="lemon"/>
            <geom pos="0.6 0.5 0.07" mesh="lemon_mesh" type="mesh" solimp="0.998 0.998 0.001" solref="0.001 1" density="50" friction="0.95 0.3 0.1" material="lemon" contype="1" conaffinity="1" condim="4"/>
        </body> -->

       <body name="milk" pos="-0.2 0.5 0.06"> 
            <joint type="free" name="milk"/>
            <geom mesh="milk_mesh" type="mesh" solimp="0.998 0.998 0.001" solref="0.001 1" density="50" friction="0.95 0.3 0.1" material="ceramic" contype="1" conaffinity="1" condim="4"/>
        </body>

    </worldbody>

    <actuator>
        <motor name="joint0_motor" joint="joint0"/>
        <motor name="joint1_motor" joint="joint1"/>
        <motor name="joint2_motor" joint="joint2"/>
        <motor name="joint3_motor" joint="joint3"/>
        <motor name="joint4_motor" joint="joint4"/>
        <motor name="joint5_motor" joint="joint5"/>
        <motor name="finger_joint_motor" joint="joint_thumb"/>
    </actuator>

    <equality>
        <joint joint1="joint_thumb" joint2="joint_index" polycoef="0 1 0 0 0"/>
        <joint joint1="joint_thumb" joint2="joint_pinky" polycoef="0 1 0 0 0"/>
    </equality>

</mujoco>

